2020-01-27 14:16:50,179 INFO: Microblog startup [in /Users/michaellaird/Development/Projects/my-first-flask-app/app/__init__.py:45]
2020-01-27 14:28:29,471 INFO: Microblog startup [in /Users/michaellaird/Development/Projects/my-first-flask-app/app/__init__.py:45]
2020-01-27 14:28:39,602 INFO: Microblog startup [in /Users/michaellaird/Development/Projects/my-first-flask-app/app/__init__.py:45]
2020-01-27 14:28:46,492 INFO: Microblog startup [in /Users/michaellaird/Development/Projects/my-first-flask-app/app/__init__.py:45]
2020-01-27 15:58:13,916 INFO: Microblog startup [in /Users/michaellaird/Development/Projects/my-first-flask-app/app/__init__.py:45]
2020-01-27 16:02:44,279 ERROR: Exception on /user/mgl [GET] [in /Users/michaellaird/Development/Projects/my-first-flask-app/venv/lib/python3.7/site-packages/flask/app.py:1891]
Traceback (most recent call last):
  File "/Users/michaellaird/Development/Projects/my-first-flask-app/venv/lib/python3.7/site-packages/flask/app.py", line 2446, in wsgi_app
    response = self.full_dispatch_request()
  File "/Users/michaellaird/Development/Projects/my-first-flask-app/venv/lib/python3.7/site-packages/flask/app.py", line 1951, in full_dispatch_request
    rv = self.handle_user_exception(e)
  File "/Users/michaellaird/Development/Projects/my-first-flask-app/venv/lib/python3.7/site-packages/flask/app.py", line 1820, in handle_user_exception
    reraise(exc_type, exc_value, tb)
  File "/Users/michaellaird/Development/Projects/my-first-flask-app/venv/lib/python3.7/site-packages/flask/_compat.py", line 39, in reraise
    raise value
  File "/Users/michaellaird/Development/Projects/my-first-flask-app/venv/lib/python3.7/site-packages/flask/app.py", line 1949, in full_dispatch_request
    rv = self.dispatch_request()
  File "/Users/michaellaird/Development/Projects/my-first-flask-app/venv/lib/python3.7/site-packages/flask/app.py", line 1935, in dispatch_request
    return self.view_functions[rule.endpoint](**req.view_args)
  File "/Users/michaellaird/Development/Projects/my-first-flask-app/venv/lib/python3.7/site-packages/flask_login/utils.py", line 261, in decorated_view
    return func(*args, **kwargs)
  File "/Users/michaellaird/Development/Projects/my-first-flask-app/app/routes.py", line 75, in user
    return render_template('user.html', user=user, posts=posts)
  File "/Users/michaellaird/Development/Projects/my-first-flask-app/venv/lib/python3.7/site-packages/flask/templating.py", line 140, in render_template
    ctx.app,
  File "/Users/michaellaird/Development/Projects/my-first-flask-app/venv/lib/python3.7/site-packages/flask/templating.py", line 120, in _render
    rv = template.render(context)
  File "/Users/michaellaird/Development/Projects/my-first-flask-app/venv/lib/python3.7/site-packages/jinja2/asyncsupport.py", line 76, in render
    return original_render(self, *args, **kwargs)
  File "/Users/michaellaird/Development/Projects/my-first-flask-app/venv/lib/python3.7/site-packages/jinja2/environment.py", line 1008, in render
    return self.environment.handle_exception(exc_info, True)
  File "/Users/michaellaird/Development/Projects/my-first-flask-app/venv/lib/python3.7/site-packages/jinja2/environment.py", line 780, in handle_exception
    reraise(exc_type, exc_value, tb)
  File "/Users/michaellaird/Development/Projects/my-first-flask-app/venv/lib/python3.7/site-packages/jinja2/_compat.py", line 37, in reraise
    raise value.with_traceback(tb)
  File "/Users/michaellaird/Development/Projects/my-first-flask-app/app/templates/user.html", line 1, in top-level template code
    {% extends "base.html" %}
  File "/Users/michaellaird/Development/Projects/my-first-flask-app/venv/lib/python3.7/site-packages/jinja2/environment.py", line 1005, in render
    return concat(self.root_render_func(self.new_context(vars)))
  File "/Users/michaellaird/Development/Projects/my-first-flask-app/app/templates/user.html", line 14, in root
    {% elif not current_user.is_following(user) %}
  File "/Users/michaellaird/Development/Projects/my-first-flask-app/app/templates/base.html", line 54, in root
  File "/Users/michaellaird/Development/Projects/my-first-flask-app/app/templates/user.html", line 49, in block_content
  File "/Users/michaellaird/Development/Projects/my-first-flask-app/venv/lib/python3.7/site-packages/jinja2/runtime.py", line 262, in call
    return __obj(*args, **kwargs)
  File "/Users/michaellaird/Development/Projects/my-first-flask-app/venv/lib/python3.7/site-packages/jinja2/runtime.py", line 630, in _fail_with_undefined_error
    raise self._undefined_exception(hint)
jinja2.exceptions.UndefinedError: 'app.models.User object' has no attribute 'is_following'
2020-01-27 16:02:54,071 ERROR: Exception on /user/mgl [GET] [in /Users/michaellaird/Development/Projects/my-first-flask-app/venv/lib/python3.7/site-packages/flask/app.py:1891]
Traceback (most recent call last):
  File "/Users/michaellaird/Development/Projects/my-first-flask-app/venv/lib/python3.7/site-packages/flask/app.py", line 2446, in wsgi_app
    response = self.full_dispatch_request()
  File "/Users/michaellaird/Development/Projects/my-first-flask-app/venv/lib/python3.7/site-packages/flask/app.py", line 1951, in full_dispatch_request
    rv = self.handle_user_exception(e)
  File "/Users/michaellaird/Development/Projects/my-first-flask-app/venv/lib/python3.7/site-packages/flask/app.py", line 1820, in handle_user_exception
    reraise(exc_type, exc_value, tb)
  File "/Users/michaellaird/Development/Projects/my-first-flask-app/venv/lib/python3.7/site-packages/flask/_compat.py", line 39, in reraise
    raise value
  File "/Users/michaellaird/Development/Projects/my-first-flask-app/venv/lib/python3.7/site-packages/flask/app.py", line 1949, in full_dispatch_request
    rv = self.dispatch_request()
  File "/Users/michaellaird/Development/Projects/my-first-flask-app/venv/lib/python3.7/site-packages/flask/app.py", line 1935, in dispatch_request
    return self.view_functions[rule.endpoint](**req.view_args)
  File "/Users/michaellaird/Development/Projects/my-first-flask-app/venv/lib/python3.7/site-packages/flask_login/utils.py", line 261, in decorated_view
    return func(*args, **kwargs)
  File "/Users/michaellaird/Development/Projects/my-first-flask-app/app/routes.py", line 75, in user
    return render_template('user.html', user=user, posts=posts)
  File "/Users/michaellaird/Development/Projects/my-first-flask-app/venv/lib/python3.7/site-packages/flask/templating.py", line 140, in render_template
    ctx.app,
  File "/Users/michaellaird/Development/Projects/my-first-flask-app/venv/lib/python3.7/site-packages/flask/templating.py", line 120, in _render
    rv = template.render(context)
  File "/Users/michaellaird/Development/Projects/my-first-flask-app/venv/lib/python3.7/site-packages/jinja2/asyncsupport.py", line 76, in render
    return original_render(self, *args, **kwargs)
  File "/Users/michaellaird/Development/Projects/my-first-flask-app/venv/lib/python3.7/site-packages/jinja2/environment.py", line 1008, in render
    return self.environment.handle_exception(exc_info, True)
  File "/Users/michaellaird/Development/Projects/my-first-flask-app/venv/lib/python3.7/site-packages/jinja2/environment.py", line 780, in handle_exception
    reraise(exc_type, exc_value, tb)
  File "/Users/michaellaird/Development/Projects/my-first-flask-app/venv/lib/python3.7/site-packages/jinja2/_compat.py", line 37, in reraise
    raise value.with_traceback(tb)
  File "/Users/michaellaird/Development/Projects/my-first-flask-app/app/templates/user.html", line 1, in top-level template code
    {% extends "base.html" %}
  File "/Users/michaellaird/Development/Projects/my-first-flask-app/venv/lib/python3.7/site-packages/jinja2/environment.py", line 1005, in render
    return concat(self.root_render_func(self.new_context(vars)))
  File "/Users/michaellaird/Development/Projects/my-first-flask-app/app/templates/user.html", line 14, in root
    {% elif not current_user.is_following(user) %}
  File "/Users/michaellaird/Development/Projects/my-first-flask-app/app/templates/base.html", line 54, in root
  File "/Users/michaellaird/Development/Projects/my-first-flask-app/app/templates/user.html", line 49, in block_content
  File "/Users/michaellaird/Development/Projects/my-first-flask-app/venv/lib/python3.7/site-packages/jinja2/runtime.py", line 262, in call
    return __obj(*args, **kwargs)
  File "/Users/michaellaird/Development/Projects/my-first-flask-app/venv/lib/python3.7/site-packages/jinja2/runtime.py", line 630, in _fail_with_undefined_error
    raise self._undefined_exception(hint)
jinja2.exceptions.UndefinedError: 'app.models.User object' has no attribute 'is_following'
